# Python中的Traceback详解

Traceback（回溯）是Python解释器在遇到未处理异常时提供的错误报告，它显示了从错误发生点到程序入口的完整调用链。

## Traceback的基本结构

一个典型的traceback包含以下部分：

1. **Traceback信息头**：指出这是一个traceback
2. **调用栈帧**：从下到上显示函数调用链
3. **错误位置**：显示错误发生的文件和行号
4. **错误代码**：显示引发错误的实际代码行
5. **错误类型和消息**：具体的异常类型和描述

示例traceback：
```
Traceback (most recent call last):
  File "example.py", line 10, in <module>
    result = divide(10, 0)
  File "example.py", line 5, in divide
    return numerator / denominator
ZeroDivisionError: division by zero
```

## Traceback各部分的详细解释

### 1. 调用栈帧

每个栈帧显示：
- 文件名
- 行号
- 模块/函数名
- 实际代码行（在终端/IDE中显示）

栈帧顺序：
- **最下面**的是最初调用的位置（程序入口）
- **最上面**的是实际引发错误的位置

### 2. 错误类型和消息

最后一行显示：
- 异常类型（如`ZeroDivisionError`）
- 异常消息（如`division by zero`）

## Traceback的常见类型

1. **简单Traceback**：
   ```
   Traceback (most recent call last):
     File "<stdin>", line 1, in <module>
   NameError: name 'x' is not defined
   ```

2. **多层调用Traceback**：
   ```
   Traceback (most recent call last):
     File "app.py", line 12, in <module>
       main()
     File "app.py", line 8, in main
       process_data()
     File "app.py", line 4, in process_data
       return data / len(data)
   ZeroDivisionError: division by zero
   ```

3. **链式异常Traceback**（Python 3+）：
   ```
   Traceback (most recent call last):
     File "app.py", line 6, in <module>
       x = 1 / 0
   ZeroDivisionError: division by zero
   
   During handling of the above exception, another exception occurred:
   
   Traceback (most recent call last):
     File "app.py", line 8, in <module>
       raise ValueError("New error") from None
   ValueError: New error
   ```

## 如何阅读和利用Traceback

1. **从下往上读**：
   - 先看最后一行了解错误类型
   - 然后向上追踪调用链

2. **定位问题**：
   - 查看错误发生的具体文件和行号
   - 检查错误行附近的代码逻辑

3. **调试技巧**：
   - 在错误位置附近添加`print()`语句
   - 使用调试器在关键点设置断点

## 处理Traceback的实用技巧

1. **捕获并记录完整Traceback**：
```python
import traceback
import sys

try:
    # 可能出错的代码
    1 / 0
except:
    exc_type, exc_value, exc_traceback = sys.exc_info()
    traceback_details = traceback.format_exception(exc_type, exc_value, exc_traceback)
    print("".join(traceback_details))
```

2. **获取当前调用栈**（用于调试）：
```python
import traceback
print(traceback.format_stack())
```

3. **简化Traceback输出**（Python 3.10+）：
```python
try:
    1 / 0
except Exception as e:
    print(f"{type(e).__name__}: {e}")  # 输出: ZeroDivisionError: division by zero
```

理解Traceback是调试Python程序的关键技能，它能帮助开发者快速定位问题根源，提高调试效率。